Workbook
Name \b: #REF!
Name \c: #REF!
Name \d: #REF!
Name \e: #REF!
Name \f: #REF!
Name \g: #REF!
Name \h: #REF!
Name \o: #REF!
Name A: #REF!
Name BLANK: #REF!
Name C_: #REF!
Name CODE: #REF!
Name COMBINE: #REF!
Name CONFM: #REF!
Name DIST1: #REF!
Name DIST2: #REF!
Name EMPTY: #REF!
Name HA: #REF!
Name HB: #REF!
Name HCH: #REF!
Name HCNR: #REF!
Name HD: #REF!
Name HDK: #REF!
Name HELP: #REF!
Name HES: #REF!
Name HF: #REF!
Name HGR: #REF!
Name HIR: #REF!
Name HIT: #REF!
Name HN: #REF!
Name HNL: #REF!
Name HOMOLO: #REF!
Name HP: #REF!
Name HS: #REF!
Name HSF: #REF!
Name HUK: #REF!
Name Print_Area_MI: #REF!
Name Spec1: 車両情報一覧!$D$2:$D$302
Name Spec2: 車両情報一覧!$G$2:$G$302
Name Spec3: 車両情報一覧!$J$2:$J$302
Name Spec4: 車両情報一覧!$M$2:$M$302
Name Spec5: 車両情報一覧!$P$2:$P$302
Name SpecList: 必要大分類!$B$3:$B$200
Name あ: #REF!
Name タイトル: #REF!
Name 注釈: #REF!
Name 導入国あり欄: [1]備考!$B$2:$B$2
Name 導入国型式リストのカテゴリー: [1]備考!$A$2:$A$33

Sheet 車両情報一覧
A1: No. | B1: 車両条件 | C1: AND/OR | D1: 大分類1 | E1: 細目1 | F1: not | G1: 大分類2 | H1: 細目2 | I1: not | J1: 大分類3 | K1: 細目3 | L1: not | M1: 大分類4 | N1: 細目4 | O1: not | P1: 大分類5 | Q1: 細目5 | R1: not
A2: =ROW()-1 | B2: BSMあり | D2: U4N | E2: C,D,E,F,G,H,J,K | F2: FALSE | I2: FALSE | L2: FALSE | O2: FALSE | R2: FALSE
A3: =ROW()-1 | B3: RCTAあり | D3: U4B | E3: F,G,H,K,L,P,Q,S,T,U | F3: FALSE | I3: FALSE | L3: FALSE | O3: FALSE | R3: FALSE
A4: =ROW()-1 | B4: SEAあり | D4: U4N | E4: G,H,J,K,P,Q | F4: FALSE | I4: FALSE | L4: FALSE | O4: FALSE | R4: FALSE
A5: =ROW()-1 | B5: FHLあり | D5: U4N | E5: D,F,H,K | F5: FALSE | I5: FALSE | L5: FALSE | O5: FALSE | R5: FALSE
A6: =ROW()-1 | B6: SCB(RIS)あり | D6: 車両条件 | E6: FHLあり | F6: FALSE | I6: FALSE | L6: FALSE | O6: FALSE | R6: FALSE
A7: =ROW()-1 | B7: RVAIあり | D7: 車両条件 | E7: FHLあり | F7: FALSE | I7: FALSE | L7: FALSE | O7: FALSE | R7: FALSE
A8: =ROW()-1 | B8: AVSあり | C8: AND | D8: 車両条件 | E8: BSMあり | F8: FALSE | G8: DESTINA | H8: DOMEST | I8: FALSE | L8: FALSE | O8: FALSE | R8: FALSE
A9: =ROW()-1 | B9: VSC-VDIMあり | C9: OR | D9: G3L | E9: B,C,D,E,F,G,H,I,J,K,L | F9: FALSE | G9: G3R | H9: B | I9: FALSE | L9: FALSE | O9: FALSE | R9: FALSE
A10: =ROW()-1 | B10: BSM付きミラー | D10: L8A | E10: C,E,G,H | F10: FALSE | I10: FALSE | L10: FALSE | O10: FALSE | R10: FALSE
A11: =ROW()-1 | B11: MIDあり | D11: T3P | E11: B | F11: FALSE | I11: FALSE | L11: FALSE | O11: FALSE | R11: FALSE
A12: =ROW()-1 | B12: バックモニターあり | D12: U4C | E12: D,E | F12: FALSE | I12: FALSE | L12: FALSE | O12: FALSE | R12: FALSE
A13: =ROW()-1 | B13: RCTA動的判定(AVN)あり | D13: ― | E13: ― | F13: FALSE | I13: FALSE | L13: FALSE | O13: FALSE | R13: FALSE
A14: =ROW()-1 | B14: CAN接続ありMM | D14: U1A | E14: D,E,F,H | F14: FALSE | I14: FALSE | L14: FALSE | O14: FALSE | R14: FALSE
A15: =ROW()-1 | B15: RCTABあり | D15: U4B | E15: K,L | F15: FALSE | I15: FALSE | L15: FALSE | O15: FALSE | R15: FALSE
A16: =ROW()-1 | B16: クルコンありor運マネ有 | C16: OR | D16: D4N | E16: C,D | F16: FALSE | G16: G3V | H16: B | I16: FALSE | L16: FALSE | O16: FALSE | R16: FALSE
A17: =ROW()-1 | B17: SEA対応バッテリ | D17: T1B | E17: B,C,D,K,L | F17: FALSE | I17: FALSE | L17: FALSE | O17: FALSE | R17: FALSE
A18: =ROW()-1 | B18: 19ePFv2以降 | D18: U4N | E18: ALL | F18: FALSE | I18: FALSE | L18: FALSE | O18: FALSE | R18: FALSE
A19: =ROW()-1 | B19: SEAあり(ドア制御あり) | C19: AND | D19: 車両条件 | E19: SEAあり | F19: FALSE | G19: 車両条件 | H19: e-latch-PSDあり | I19: FALSE | L19: FALSE | O19: FALSE | R19: FALSE
A20: =ROW()-1 | B20: 21MMupgrade以降 | D20: U1A | E20: D,E,F,H | F20: FALSE | I20: FALSE | L20: FALSE | O20: FALSE | R20: FALSE
A21: =ROW()-1 | B21: 電波法導入可 | D21: SRR520 | E21: ◎ | F21: FALSE | I21: FALSE | L21: FALSE | O21: FALSE | R21: FALSE | T21: SRR320 (#3 / #3.5 / #3.6 / #3.7) | U21: SRR520 | V21: DNSRR003 (#1) | W21: DNSRR004 (#1.5)
A22: =ROW()-1 | B22: BSM導入可 | C22: AND | D22: BSM detection (Width type of BSM Warning zone) | E22: ◎/Narrow,◎/Wide | F22: FALSE | G22: 車両条件 | H22: 電波法導入可 | I22: FALSE | L22: FALSE | O22: FALSE | R22: FALSE
A23: =ROW()-1 | B23: RCTA導入可 | C23: AND | D23: RCTA detection (Length of RCTA Warning zone (LINE_L2)) | E23: ◎/5m,◎/6m,◎/7m | F23: FALSE | G23: 車両条件 | H23: 電波法導入可 | I23: FALSE | L23: FALSE | O23: FALSE | R23: FALSE
A24: =ROW()-1 | B24: SEA導入可 | C24: AND | D24: CNSRR320 GBT非適用 Final decision for introduction (SEA) GB/T(SEA) 非適用車両 ※Continental only | E24: OK | F24: FALSE | G24: 車両条件 | H24: 電波法導入可 | I24: FALSE | L24: FALSE | O24: FALSE | R24: FALSE | T24: CNSRR320 GBT非適用 Final decision for introduction (SEA) GB/T(SEA) 非適用車両 ※Continental only | U24: CNSRR320 GBT適用 Final decision for introduction (SEA) ▽R GB/T(SEA)適用車両 ※Continental only | V24: CNSRR520 Final decision for introduction (SEA) ※Continental only | W24: DNTSS4 Final decision for introduction (SEA) ※Denso(TSS4) only
A25: =ROW()-1 | B25: FHL導入可 | C25: AND | D25: CNSRR320520 Final decision for introduction (FHL) ※Continental only | E25: OK | F25: FALSE | G25: 車両条件 | H25: 電波法導入可 | I25: FALSE | L25: FALSE | O25: FALSE | R25: FALSE | T25: CNSRR320520 Final decision for introduction (FHL) ※Continental only | U25: DNTSS4 Final decision for introduction (FHL) ※Denso(TSS4) only
A26: =ROW()-1 | B26: SCB(RIS)導入可 | C26: AND | D26: CNSRR520 Final decision for introduction SCB(RIS) ※Continental(SRR5) only | E26: OK | F26: FALSE | G26: 車両条件 | H26: 電波法導入可 | I26: FALSE | L26: FALSE | O26: FALSE | R26: FALSE | T26: CNSRR520 Final decision for introduction SCB(RIS) ※Continental(SRR5) only | U26: DNTSS4 Final decision for introduction SCB(RIS) ※Denso(TSS4) only
A27: =ROW()-1 | B27: RVAI導入可 | C27: AND | D27: CNSRR520 Final decision for introduction RVAI ※Continental(SRR5) only | E27: OK | F27: FALSE | G27: 車両条件 | H27: 電波法導入可 | I27: FALSE | L27: FALSE | O27: FALSE | R27: FALSE | T27: CNSRR520 Final decision for introduction RVAI ※Continental(SRR5) only | U27: DNTSS4 Final decision for introduction RVAI ※Denso(TSS4) only
A28: =ROW()-1 | B28: AVS導入可 | C28: AND | D28: CNSRR520 Final decision for introduction AVS ※Continental(SRR5) only | E28: OK | F28: FALSE | G28: 車両条件 | H28: 電波法導入可 | I28: FALSE | L28: FALSE | O28: FALSE | R28: FALSE | T28: CNSRR520 Final decision for introduction AVS ※Continental(SRR5) only | U28: DNTSS4 Final decision for introduction AVS ※Denso(TSS4) only
A29: =ROW()-1 | B29: 寒冷地仕様 | D29: ― | E29: ― | F29: FALSE | I29: FALSE | L29: FALSE | O29: FALSE | R29: FALSE
A30: =ROW()-1 | B30: D席ECミラー | D30: L8A | E30: B,C,E,G,H | F30: FALSE | I30: FALSE | L30: FALSE | O30: FALSE | R30: FALSE
A31: =ROW()-1 | B31: エコラン | D31: B2H | E31: B | F31: FALSE | I31: FALSE | L31: FALSE | O31: FALSE | R31: FALSE
A32: =ROW()-1 | B32: 生産工場 | D32: ― | E32: ― | F32: FALSE | I32: FALSE | L32: FALSE | O32: FALSE | R32: FALSE
A33: =ROW()-1 | B33: MT車 | D33: T/M | E33: ― | F33: FALSE | I33: FALSE | L33: FALSE | O33: FALSE | R33: FALSE
A34: =ROW()-1 | B34: DRSあり | D34: G1E | E34: B,C | F34: FALSE | I34: FALSE | L34: FALSE | O34: FALSE | R34: FALSE
A35: =ROW()-1 | B35: Rrバンパ | D35: K1C | E35: ALL | F35: FALSE | I35: FALSE | L35: FALSE | O35: FALSE | R35: FALSE
A36: =ROW()-1 | B36: 電子PF | D36: ― | E36: ― | F36: FALSE | I36: FALSE | L36: FALSE | O36: FALSE | R36: FALSE
A37: =ROW()-1 | B37: リヤコンビランプ | D37: L7A | E37: ALL | F37: FALSE | I37: FALSE | L37: FALSE | O37: FALSE | R37: FALSE
A38: =ROW()-1 | B38: ESSあり | D38: L7N | E38: B,C,D | F38: FALSE | I38: FALSE | L38: FALSE | O38: FALSE | R38: FALSE
A39: =ROW()-1 | B39: ブレーキ | D39: G3G | E39: ALL | F39: FALSE | I39: FALSE | L39: FALSE | O39: FALSE | R39: FALSE
A40: =ROW()-1 | B40: e-latch-PSDあり | D40: L2F | E40: E | F40: FALSE | I40: FALSE | L40: FALSE | O40: FALSE | R40: FALSE
...

Sheet 記載方法
A1: No. | B1: 車両条件 | C1: 記載方法
A2: =車両情報一覧!A2 | B2: =車両情報一覧!B2 | C2: メーカオプション(工場装着)のBSMが設定される細目を設定 用品BSM(ILA装着含む)は設定しない 標準外細目が使われる場合は細目を変更すること
A3: =車両情報一覧!A3 | B3: =車両情報一覧!B3 | C3: RCTAが設定される細目を設定 標準外細目が使われる場合は細目を変更すること
A4: =車両情報一覧!A4 | B4: =車両情報一覧!B4 | C4: SEAが設定される細目を設定 標準外細目が使われる場合は細目を変更すること
A5: =車両情報一覧!A5 | B5: =車両情報一覧!B5 | C5: FHLが設定される細目を設定 標準外細目が使われる場合は細目を変更すること
A6: =車両情報一覧!A6 | B6: =車両情報一覧!B6 | C6: SCB(RIS)が設定される細目（基本的にはFHL設定と一致）される細目を設定
A7: =車両情報一覧!A7 | B7: =車両情報一覧!B7 | C7: AVSが設定される細目（基本的にはFHL設定と一致）される細目を設定
A8: =車両情報一覧!A8 | B8: =車両情報一覧!B8 | C8: AVSなしの場合は大分類１を－に変更
A9: =車両情報一覧!A9 | B9: =車両情報一覧!B9 | C9: 車両仕様G3R、G3LにてVSC、VDIMありとなる細目を記載
A10: =車両情報一覧!A10 | B10: =車両情報一覧!B10 | C10: 車両仕様L8AにてBSMインジケータありとなる細目を記載
A11: =車両情報一覧!A11 | B11: =車両情報一覧!B11 | C11: 車両仕様T3PにてMIDありとなる細目を記載
A12: =車両情報一覧!A12 | B12: =車両情報一覧!B12 | C12: 車両仕様U4Cにてバックモニタ―ありとなる細目を記載 バックモニターがあればよいので、PVM、MTM、BGM、BMなど周辺監視モニターの種類は問わない
A13: =車両情報一覧!A13 | B13: =車両情報一覧!B13 | C13: AVNで動的判定有の場合は大分類1＝車両条件 細目1＝RCTAありを記入
... A46: =車両情報一覧!A46 | B46: =車両情報一覧!B46 | C46: 車両仕様U4WにてFSRありの細目を記載
A47: =車両情報一覧!A47 | B47: =車両情報一覧!B47
A48: =車両情報一覧!A48 | B48: =車両情報一覧!B48
A49: =車両情報一覧!A49 | B49: =車両情報一覧!B49
A50: =車両情報一覧!A50 | B50: =車両情報一覧!B50
A51: =車両情報一覧!A51 | B51: =車両情報一覧!B51
A52: =車両情報一覧!A52 | B52: =車両情報一覧!B52
A53: =車両情報一覧!A53 | B53: =車両情報一覧!B53
A54: =車両情報一覧!A54 | B54: =車両情報一覧!B54
A55: =車両情報一覧!A55 | B55: =車両情報一覧!B55
A56: =車両情報一覧!A56 | B56: =車両情報一覧!B56
A57: =車両情報一覧!A57 | B57: =車両情報一覧!B57
A58: =車両情報一覧!A58 | B58: =車両情報一覧!B58
... A168: =車両情報一覧!A168 | B168: =車両情報一覧!B168

Sheet 必要大分類
B2: Ci-Specで指定する大分類
B3: B2H
B4: D4N
B5: G1E
B6: G3G
B7: G3L
B8: G3R
B9: G3V
B10: K1B
B11: K1C
B12: L2F
B13: L6A
... B26: U4X

Sheet メモ付
A1: No. | B1: 車両条件 | C1: AND/OR | D1: 大分類1 | E1: 細目1 | F1: not | G1: 大分類2 | H1: 細目2 | I1: not | J1: 大分類3 | K1: 細目3 | L1: not | M1: 大分類4 | N1: 細目4 | O1: not | P1: 大分類5 | Q1: 細目5 | R1: not
A2: =ROW()-1 | B2: BSMあり | D2: U4N | E2: G,H,J,K | F2: FALSE | I2: FALSE | L2: FALSE | O2: FALSE | R2: FALSE
A3: =ROW()-1 | B3: RCTAあり | D3: U4N | E3: G,H,J,K | F3: FALSE | I3: FALSE | L3: FALSE | O3: FALSE | R3: FALSE
A4: =ROW()-1 | B4: SEAあり | D4: U4N | E4: G,H,J,K | F4: FALSE | I4: FALSE | L4: FALSE | O4: FALSE | R4: FALSE
A5: =ROW()-1 | B5: FHLあり | D5: U4N | E5: H,K | F5: FALSE | I5: FALSE | L5: FALSE | O5: FALSE | R5: FALSE
A6: =ROW()-1 | B6: SCB(RIS)あり | D6: U4N | E6: H,K | F6: FALSE | I6: FALSE | L6: FALSE | O6: FALSE | R6: FALSE
A7: =ROW()-1 | B7: RVAIあり | C7: AND | D7: 車両条件 | E7: FHLあり | F7: FALSE | I7: FALSE | L7: FALSE | O7: FALSE | R7: FALSE
A8: =ROW()-1 | B8: AVSあり | C8: AND | D8: 車両条件 | E8: BSMあり | F8: FALSE | G8: DESTINA | H8: ALL | I8: FALSE | L8: FALSE | O8: FALSE | R8: FALSE
A9: =ROW()-1 | B9: VSC-VDIMあり | C9: OR | D9: G3L | E9: B,C | F9: FALSE | G9: G3R | H9: B | I9: FALSE | L9: FALSE | O9: FALSE | R9: FALSE
A10: =ROW()-1 | B10: BSM付きミラー | D10: L8A | E10: C,E,G,H | F10: FALSE | I10: FALSE | L10: FALSE | O10: FALSE | R10: FALSE
A11: =ROW()-1 | B11: MIDあり | D11: T3P | E11: B | F11: FALSE | I11: FALSE | L11: FALSE | O11: FALSE | R11: FALSE
A12: =ROW()-1 | B12: バックモニターあり | D12: U4C | E12: D,E | F12: FALSE | I12: FALSE | L12: FALSE | O12: FALSE | R12: FALSE
A13: =ROW()-1 | B13: RCTA動的判定(AVN)あり | D13: U4N | E13: ― | F13: FALSE | I13: FALSE | L13: FALSE | O13: FALSE | R13: FALSE
A14: =ROW()-1 | B14: CAN接続ありMM | D14: U1A | E14: D,E,F,H | F14: FALSE | I14: FALSE | L14: FALSE | O14: FALSE | R14: FALSE
A15: =ROW()-1 | B15: RCTABあり | D15: U4B | E15: K,L | F15: FALSE | I15: FALSE | L15: FALSE | O15: FALSE | R15: FALSE
A16: =ROW()-1 | B16: クルコンありor運マネ有 | D16: D4N | E16: C,D | F16: FALSE | G16: G3V | H16: B | I16: FALSE | L16: FALSE | O16: FALSE | R16: FALSE
A17: =ROW()-1 | B17: SEA対応バッテリ | D17: T1B | E17: B,C,D | F17: FALSE | I17: FALSE | L17: FALSE | O17: FALSE | R17: FALSE
A18: =ROW()-1 | B18: 19ePFv2以降 | D18: ALL | F18: FALSE | I18: FALSE | L18: FALSE | O18: FALSE | R18: FALSE
A19: =ROW()-1 | B19: SEAあり(ドア制御あり) | C19: AND | D19: 車両条件 | E19: SEAあり | F19: FALSE | G19: L2F | H19: E | I19: FALSE | L19: FALSE | O19: FALSE | R19: FALSE
A20: =ROW()-1 | B20: 21MMupgrade以降 | D20: U1A | E20: D,E,F,H | F20: FALSE | I20: FALSE | L20: FALSE | O20: FALSE | R20: FALSE
A21: =ROW()-1 | B21: BSM導入可 | C21: AND | D21: BSM detection (Width type of BSM Warning zone) | E21: ◎/Narrow,◎/Wide | F21: FALSE | G21: 車両条件 | H21: 電波法導入可 | I21: FALSE | L21: FALSE | O21: FALSE | R21: FALSE
A22: =ROW()-1 | B22: RCTA導入可 | C22: AND | D22: RCTA detection (Length of RCTA Warning zone (LINE_L2)) | E22: ◎/5m,◎/6m,◎/7m | F22: FALSE | G22: 車両条件 | H22: 電波法導入可 | I22: FALSE | L22: FALSE | O22: FALSE | R22: FALSE
A23: =ROW()-1 | B23: SEA導入可 | C23: AND | D23: Final decision for introduction (SEA) GB/T(SEA) 非適用車両 ※Continental only | E23: OK | F23: FALSE | G23: 車両条件 | H23: 電波法導入可 | I23: FALSE | L23: FALSE | O23: FALSE | R23: FALSE | T23: Final decision for introduction (SEA) GB/T(SEA) 非適用車両 ※Continental only | U23: Final decision for introduction (SEA) ▽R GB/T(SEA)適用車両 ※Continental only | V23: Final decision for introduction (SEA) ※Continental only | W23: Final decision for introduction (SEA) ※Denso(TSS4) only
A24: =ROW()-1 | B24: FHL導入可 | C24: AND | D24: Final decision for introduction (FHL) ※Continental only | E24: OK | F24: FALSE | G24: 車両条件 | H24: 電波法導入可 | I24: FALSE | L24: FALSE | O24: FALSE | R24: FALSE | T24: Final decision for introduction (FHL) ※Continental only | U24: Final decision for introduction (FHL) ※Denso(TSS4) only
A25: =ROW()-1 | B25: SCB(RIS)導入可 | C25: AND | D25: Final decision for introduction SCB(RIS) ※Continental(SRR5) only | E25: OK | F25: FALSE | G25: 車両条件 | H25: 電波法導入可 | I25: FALSE | L25: FALSE | O25: FALSE | R25: FALSE | T25: Final decision for introduction SCB(RIS) ※Continental(SRR5) only | U25: Final decision for introduction SCB(RIS) ※Denso(TSS4) only
A26: =ROW()-1 | B26: RVAI導入可 | C26: AND | D26: Final decision for introduction RVAI ※Continental(SRR5) only | E26: OK | F26: FALSE | G26: 車両条件 | H26: 電波法導入可 | I26: FALSE | L26: FALSE | O26: FALSE | R26: FALSE | T26: Final decision for introduction RVAI ※Continental(SRR5) only | U26: Final decision for introduction RVAI ※Denso(TSS4) only
A27: =ROW()-1 | B27: AVS導入可 | C27: AND | D27: Final decision for introduction AVS ※Continental(SRR5) only | E27: OK | F27: FALSE | G27: 車両条件 | H27: 電波法導入可 | I27: FALSE | L27: FALSE | O27: FALSE | R27: FALSE | T27: Final decision for introduction AVS ※Continental(SRR5) only | U27: Final decision for introduction AVS ※Denso(TSS4) only
A28: =ROW()-1 | B28: 寒冷地仕様 | D28: ― | E28: ― | F28: FALSE | I28: FALSE | L28: FALSE | O28: FALSE | R28: FALSE
A29: =ROW()-1 | B29: D席ECミラー | D29: L8A | E29: B,C,E,G,H | F29: FALSE | I29: FALSE | L29: FALSE | O29: FALSE | R29: FALSE
A30: =ROW()-1 | B30: エコラン | D30: B2H | E30: B | F30: FALSE | I30: FALSE | L30: FALSE | O30: FALSE | R30: FALSE
A31: =ROW()-1 | B31: 生産工場 | D31: ― | E31: ― | F31: FALSE | I31: FALSE | L31: FALSE | O31: FALSE | R31: FALSE
A32: =ROW()-1 | B32: MT車 | D32: T/M | E32: ― | F32: FALSE | I32: FALSE | L32: FALSE | O32: FALSE | R32: FALSE
A33: =ROW()-1 | B33: DRSあり | D33: G1E | E33: B,C | F33: FALSE | I33: FALSE | L33: FALSE | O33: FALSE | R33: FALSE
A34: =ROW()-1 | B34: Rrバンパ | D34: K1C | E34: ALL | F34: FALSE | I34: FALSE | L34: FALSE | O34: FALSE | R34: FALSE
A35: =ROW()-1 | B35: 電子PF | D35: ― | E35: ― | F35: FALSE | I35: FALSE | L35: FALSE | O35: FALSE | R35: FALSE
A36: =ROW()-1 | B36: リヤコンビランプ | D36: L7A | E36: ALL | F36: FALSE | I36: FALSE | L36: FALSE | O36: FALSE | R36: FALSE
A37: =ROW()-1 | B37: ESSあり | D37: L7N | E37: B | F37: FALSE | I37: FALSE | L37: FALSE | O37: FALSE | R37: FALSE
A38: =ROW()-1 | B38: ブレーキ | D38: G3G | E38: ALL | F38: FALSE | I38: FALSE | L38: FALSE | O38: FALSE | R38: FALSE
A39: =ROW()-1 | B39: e-latch-PSDあり | D39: L2F | E39: E | F39: FALSE | I39: FALSE | L39: FALSE | O39: FALSE | R39: FALSE
... A43: =ROW()-1 | B43: HUDあり | D43: T3Y | E43: B,C | F43: FALSE | I43: FALSE | L43: FALSE | O43: FALSE | R43: FALSE
...

Sheet LLM判定結果
A1: row | B1: condition_no | C1: condition_name | D1: major_code | E1: major_name | F1: detail_code | G1: detail_name | H1: basis | I1: should_append | J1: reason | K1: confidence
A2: 2 | B2: =ROW()-1 | C2: BSMあり | D2: U4N | E2: REAR & REAR SIDE MONITOR | F2: I | G2: W/O | H2: メーカオプション(工場装着)のBSMが設定される細目を設定 用品BSM(ILA装着含む)は設定しない 標準外細目が使われる場合は細目を変更すること | I2: FALSE | J2: 候補細目名称「W/O」だけではメーカオプション(工場装着)のBSM有無を判断できず、設定基準への合致が確認できないため。 | K2: Low
A3: 2 | B3: =ROW()-1 | C3: BSMあり | D3: U4N | E3: REAR & REAR SIDE MONITOR | F3: M | G3: BSM(ILA) | H3: メーカオプション(工場装着)のBSMが設定される細目を設定 用品BSM(ILA装着含む)は設定しない 標準外細目が使われる場合は細目を変更すること | I3: FALSE | J3: 設定基準で「用品BSM(ILA装着含む)は設定しない」と明記されており、候補細目名称「BSM(ILA)」は除外対象に該当するため。 | K3: High
A4: 2 | B4: =ROW()-1 | C4: BSMあり | D4: U4N | E4: REAR & REAR SIDE MONITOR | F4: P | G4: BSM(LONG)+SEA+RCTA(DOP) | H4: メーカオプション(工場装着)のBSMが設定される細目を設定 用品BSM(ILA装着含む)は設定しない 標準外細目が使われる場合は細目を変更すること | I4: FALSE | J4: 候補細目名称に「(DOP)」とあり用品（ディーラーオプション）装着のBSMと判断でき、設定基準の「用品BSMは設定しない」に反するため。 | K4: High
A5: 2 | B5: =ROW()-1 | C5: BSMあり | D5: U4N | E5: REAR & REAR SIDE MONITOR | F5: Q | G5: BSM(LONG)+SEA(DOP)PREP PKG+PRE WIRE | H5: メーカオプション(工場装着)のBSMが設定される細目を設定 用品BSM(ILA装着含む)は設定しない 標準外細目が使われる場合は細目を変更すること | I5: FALSE | J5: 候補細目に「SEA(DOP)」とあり用品（ディーラーオプション）系を含むため、メーカオプション（工場装着）のBSMとして設定できない。 | K5: High
A6: 4 | B6: =ROW()-1 | C6: SEAあり | D6: U4N | E6: REAR & REAR SIDE MONITOR | F6: I | G6: W/O | H6: SEAが設定される細目を設定 標準外細目が使われる場合は細目を変更すること | I6: FALSE | J6: 候補細目名称「W/O」からSEAが設定される細目であることを判断できないため。 | K6: Low
A7: 4 | B7: =ROW()-1 | C7: SEAあり | D7: U4N | E7: REAR & REAR SIDE MONITOR | F7: M | G7: BSM(ILA) | H7: SEAが設定される細目を設定 標準外細目が使われる場合は細目を変更すること | I7: FALSE | J7: 候補細目名称「BSM(ILA)」からはSEAが設定される細目であることを判断できないため。 | K7: Low
A8: 4 | B8: =ROW()-1 | C8: SEAあり | D8: U4N | E8: REAR & REAR SIDE MONITOR | F8: C | G8: BSM(LONG) | H8: SEAが設定される細目を設定 標準外細目が使われる場合は細目を変更すること | I8: FALSE | J8: 候補細目名称「BSM(LONG)」からはSEAの設定有無が判断できず、設定基準に合致すると断定できないため。 | K8: Low
A9: 4 | B9: =ROW()-1 | C9: SEAあり | D9: U4N | E9: REAR & REAR SIDE MONITOR | F9: P | G9: BSM(LONG)+SEA+RCTA(DOP) | H9: SEAが設定される細目を設定 標準外細目が使われる場合は細目を変更すること | I9: TRUE | J9: 候補細目名称に「SEA」が含まれており、『SEAが設定される細目を設定』という設定基準に合致すると判断できるため。 | K9: High
A10: 4 | B10: =ROW()-1 | C10: SEAあり | D10: U4N | E10: REAR & REAR SIDE MONITOR | F10: Q | G10: BSM(LONG)+SEA(DOP)PREP PKG+PRE WIRE | H10: SEAが設定される細目を設定 標準外細目が使われる場合は細目を変更すること | I10: TRUE | J10: 候補細目名称に「SEA(DOP)PREP」が含まれており、SEAが設定される細目と判断できるため。 | K10: High
A11: 5 | B11: =ROW()-1 | C11: FHLあり | D11: U4N | E11: REAR & REAR SIDE MONITOR | F11: G | G11: BSM(LONG)+SEA | H11: FHLが設定される細目を設定 標準外細目が使われる場合は細目を変更すること | I11: FALSE | J11: 候補細目名称「BSM(LONG)+SEA」からはFHLが設定される細目であることを判断できないため。 | K11: Low
A12: 5 | B12: =ROW()-1 | C12: FHLあり | D12: U4N | E12: REAR & REAR SIDE MONITOR | F12: I | G12: W/O | H12: FHLが設定される細目を設定 標準外細目が使われる場合は細目を変更すること | I12: FALSE | J12: 候補細目名称「W/O」だけではFHL有無（FHLが設定される細目）を示すと判断できないため。 | K12: Low
A13: 5 | B13: =ROW()-1 | C13: FHLあり | D13: U4N | E13: REAR & REAR SIDE MONITOR | F13: M | G13: BSM(ILA) | H13: FHLが設定される細目を設定 標準外細目が使われる場合は細目を変更すること | I13: FALSE | J13: 候補細目名称「BSM(ILA)」からFHLが設定されていることを判断できず、設定基準への合致が確認できないため。 | K13: Low
... A112: 45 | B112: =ROW()-1 | C112: Frバンパ_ヘッドランプ | D112: L6A | E112: HEADLAMP | F112: Q | G112: LED HI PLUS + WEL(SUV) | H112: 変更不要 | I112: FALSE | J112: 条件の設定基準が「変更不要」と明記されているため、候補細目名称を追記する必要がないと判断できる。 | K112: High

Sheet 標準細目チェック
A1: level | B1: category | C1: major_code | D1: detail_code | E1: country_detail_name | F1: standard_name_en | G1: standard_name_kana | H1: vehicle_row | I1: vehicle_condition_no | J1: vehicle_condition_name | K1: message
A2: Warning | B2: 標準名称不一致 | C2: G3G | D2: J | E2: 10" BOOSTER | F2: AHB-C | G2: AHB-C | K2: 国別仕様の細目名称が標準マスタ（英語/カナ）と一致しません。
A3: Warning | B3: 標準名称不一致 | C3: L6A | D3: M | E3: LED HIGH + WEL (PU) | F3: LED | G3: LED | K3: 国別仕様の細目名称が標準マスタ（英語/カナ）と一致しません。
A4: Warning | B4: 標準名称不一致 | C4: L6A | D4: P | E4: LED HIGH + WEL (SUV) | F4: LED HIGH | G4: LED HIGH | K4: 国別仕様の細目名称が標準マスタ（英語/カナ）と一致しません。
A5: Warning | B5: 標準名称不一致 | C5: L6A | D5: T | E5: LED BASE (PU) | F5: LED BASE | G5: LED BASE | K5: 国別仕様の細目名称が標準マスタ（英語/カナ）と一致しません。
A6: Warning | B6: 標準名称不一致 | C6: L6A | D6: Q | E6: LED HI PLUS + WEL(SUV) | F6: LED HIGH W/DECORATION | G6: LED HIGH ｶｼｮｸｱﾘ | K6: 国別仕様の細目名称が標準マスタ（英語/カナ）と一致しません。
A7: Warning | B7: 標準名称不一致 | C7: L7A | D7: G | E7: FOR PICK-UP LED TYPE | F7: T:BULB S:LED BASE W/DECO | G7: T:BULB S:LED BASE ｶｼｮｸｱﾘ | K7: 国別仕様の細目名称が標準マスタ（英語/カナ）と一致しません。
A8: Warning | B8: 標準名称不一致 | C8: L7A | D8: E | E8: FOR SUV LED HIGH TYPE | F8: T:BULB S:BULB HIGH W/DECO | G8: T:BULB S:BULB HIGH ｶｼｮｸｱﾘ | K8: 国別仕様の細目名称が標準マスタ（英語/カナ）と一致しません。
A9: Warning | B9: 標準名称不一致 | C9: L7A | D9: B | E9: FOR PICK-UP BULB TYPE | F9: T:BULB S:BULB BASE | G9: T:BULB S:BULB BASE | K9: 国別仕様の細目名称が標準マスタ（英語/カナ）と一致しません。
A10: Warning | B10: 標準名称不一致 | C10: L7A | D10: D | E10: FOR C&C BULB TYPE | F10: T:BULB S:BULB HIGH | G10: T:BULB S:BULB HIGH | K10: 国別仕様の細目名称が標準マスタ（英語/カナ）と一致しません。
A11: Warning | B11: 標準名称不一致 | C11: L7A | D11: F | E11: FOR SUV LED TYPE | F11: T:BULB S:LED BASE | G11: T:BULB S:LED BASE | K11: 国別仕様の細目名称が標準マスタ（英語/カナ）と一致しません。
A12: Warning | B12: 標準名称不一致 | C12: L7A | D12: H | E12: FOR SUV LED HI PLUS TYPE | F12: T:BULB S:LED HIGH | G12: T:BULB S:LED HIGH | K12: 国別仕様の細目名称が標準マスタ（英語/カナ）と一致しません。
A13: Warning | B13: 標準名称不一致 | C13: L8B | D13: C | E13: EC MIRROR(NO MAP LAMP) | F13: EC | G13: EC | K13: 国別仕様の細目名称が標準マスタ（英語/カナ）と一致しません。
... A18: Warning | B18: 標準名称不一致 | C18: U4F | D18: F | E18: TRANSLOG(OBD) PREP PKG | F18: 5G(W/ SOS) | G18: 5G(W/ SOS) | K18: 国別仕様の細目名称が標準マスタ（英語/カナ）と一致しません。
A19: Caution | B19: 標準化未実施細目 | C19: T3P | D19: B | E19: HIGH | F19: WITH | G19: ｱﾘ | H19: 11 | I19: =ROW()-1 | J19: MIDあり | K19: 車両情報一覧に記載されていますが、標準マスタでは標準化未実施です。
A20: Caution | B20: 標準化未実施細目 | C20: U1A | D20: D | F20: 24MM 10.5" T2/T-PREM | G20: 24MM 10.5" T2/T-PREM | H20: 14 | I20: =ROW()-1 | J20: CAN接続ありMM | K20: 車両情報一覧に記載されていますが、標準マスタでは標準化未実施です。
A21: Caution | B21: 標準化未実施細目 | C21: U1A | D21: E | F21: 21MM 12.3" T2/T-PREM | G21: 21MM 12.3" T2/T-PREM | H21: 14 | I21: =ROW()-1 | J21: CAN接続ありMM | K21: 車両情報一覧に記載されていますが、標準マスタでは標準化未実施です。
A22: Caution | B22: 標準化未実施細目 | C22: U1A | D22: F | F22: 24MM 12.3 T2/T-PREM | G22: 24MM 12.3 T2/T-PREM | H22: 14 | I22: =ROW()-1 | J22: CAN接続ありMM | K22: 車両情報一覧に記載されていますが、標準マスタでは標準化未実施です。
A23: Caution | B23: 標準化未実施細目 | C23: U1A | D23: H | E23: 12.3INCH EDA#3 DAB | F23: 24MM 14" T1 | G23: 24MM 14" T1 | H23: 14 | I23: =ROW()-1 | J23: CAN接続ありMM | K23: 車両情報一覧に記載されていますが、標準マスタでは標準化未実施です。
A24: Caution | B24: 標準化未実施細目 | C24: U1A | D24: D | F24: 24MM 10.5" T2/T-PREM | G24: 24MM 10.5" T2/T-PREM | H24: 20 | I24: =ROW()-1 | J24: 21MMupgrade以降 | K24: 車両情報一覧に記載されていますが、標準マスタでは標準化未実施です。
A25: Caution | B25: 標準化未実施細目 | C25: U1A | D25: E | F25: 21MM 12.3" T2/T-PREM | G25: 21MM 12.3" T2/T-PREM | H25: 20 | I25: =ROW()-1 | J25: 21MMupgrade以降 | K25: 車両情報一覧に記載されていますが、標準マスタでは標準化未実施です。
A26: Caution | B26: 標準化未実施細目 | C26: U1A | D26: F | F26: 24MM 12.3 T2/T-PREM | G26: 24MM 12.3 T2/T-PREM | H26: 20 | I26: =ROW()-1 | J26: 21MMupgrade以降 | K26: 車両情報一覧に記載されていますが、標準マスタでは標準化未実施です。
A27: Caution | B27: 標準化未実施細目 | C27: U1A | D27: H | E27: 12.3INCH EDA#3 DAB | F27: 24MM 14" T1 | G27: 24MM 14" T1 | H27: 20 | I27: =ROW()-1 | J27: 21MMupgrade以降 | K27: 車両情報一覧に記載されていますが、標準マスタでは標準化未実施です。
A28: Caution | B28: 標準化未実施細目 | C28: L8A | D28: B | F28: HE+MEM+A/R | G28: HE+MEM+A/R | H28: 30 | I28: =ROW()-1 | J28: D席ECミラー | K28: 車両情報一覧に記載されていますが、標準マスタでは標準化未実施です。
